<?xml version="1.0" ?>
<robot name="ika" xmlns:xacro="http://ros.org/wiki/xacro">

  <!-- Materials -->
  <material name="blue"><color rgba="0 0 0.8 1"/></material>
  <material name="black"><color rgba="0 0 0 1"/></material>
  <material name="grey"><color rgba="0.5 0.5 0.5 1"/></material>

  <!-- base_footprint -->
  <link name="base_footprint"/>

  <joint name="base_joint" type="fixed">
    <parent link="base_footprint"/>
    <child link="base_link"/>
    <origin xyz="0 0 0.36" rpy="0 0 0"/>
  </joint>

  <!-- base_link (1.3m x 1.15m x 0.72m) -->
  <link name="base_link">
    <visual>
      <geometry><box size="1.3 1.15 0.72"/></geometry>
      <material name="blue"/>
    </visual>
    <collision>
      <geometry><box size="1.3 1.15 0.72"/></geometry>
    </collision>
    <inertial>
      <mass value="50.0"/>
      <origin xyz="0 0 0" rpy="0 0 0"/>
      <inertia ixx="10.0" ixy="0" ixz="0" iyy="10.0" iyz="0" izz="15.0"/>
    </inertial>
  </link>

  <!-- Wheel Macro -->
  <xacro:macro name="wheel" params="prefix x y">
    <link name="${prefix}_wheel">
      <visual>
        <origin rpy="1.5707 0 0" xyz="0 0 0"/>
        <geometry><cylinder radius="0.2" length="0.08"/></geometry>
        <material name="black"/>
      </visual>
      <collision>
        <origin rpy="1.5707 0 0" xyz="0 0 0"/>
        <geometry><cylinder radius="0.2" length="0.08"/></geometry>
      </collision>
      <inertial>
        <mass value="2.5"/>
        <origin xyz="0 0 0" rpy="0 0 0"/>
        <inertia ixx="0.03" ixy="0" ixz="0" iyy="0.03" iyz="0" izz="0.05"/>
      </inertial>
    </link>
    <joint name="${prefix}_wheel_joint" type="continuous">
      <parent link="base_link"/>
      <child link="${prefix}_wheel"/>
      <origin xyz="${x} ${y} -0.16" rpy="0 0 0"/>
      <axis xyz="0 1 0"/>
    </joint>
  </xacro:macro>

  <xacro:wheel prefix="rl" x="-0.4" y="0.575"/>
  <xacro:wheel prefix="rr" x="-0.4" y="-0.575"/>
  <xacro:wheel prefix="fl" x="0.4" y="0.575"/>
  <xacro:wheel prefix="fr" x="0.4" y="-0.575"/>

  <!-- LiDAR -->
  <link name="lidar_link">
    <visual><geometry><cylinder radius="0.05" length="0.05"/></geometry><material name="black"/></visual>
  </link>
  <joint name="lidar_joint" type="fixed">
    <parent link="base_link"/><child link="lidar_link"/><origin xyz="0.5 0 0.385" rpy="0 0 0"/>
  </joint>

  <!-- Camera -->
  <link name="camera_link">
    <visual><geometry><box size="0.05 0.1 0.05"/></geometry><material name="grey"/></visual>
  </link>
  <joint name="camera_joint" type="fixed">
    <parent link="base_link"/><child link="camera_link"/><origin xyz="0.65 0 0.2" rpy="0 0 0"/>
  </joint>

  <!-- Gazebo Control & Sensors -->
  <gazebo>
    <plugin name="diff_drive" filename="libgazebo_ros_diff_drive.so">
      <ros><remapping>cmd_vel:=cmd_vel</remapping><remapping>odom:=odom</remapping></ros>
      <left_joint>rl_wheel_joint</left_joint>
      <right_joint>rr_wheel_joint</right_joint>
      <wheel_separation>1.15</wheel_separation>
      <wheel_diameter>0.4</wheel_diameter>
      <max_wheel_torque>200</max_wheel_torque>
      <max_wheel_acceleration>1.0</max_wheel_acceleration>
      <publish_odom>true</publish_odom>
      <publish_odom_tf>true</publish_odom_tf>
      <publish_wheel_tf>true</publish_wheel_tf>
      <odometry_frame>odom</odometry_frame>
      <robot_base_frame>base_footprint</robot_base_frame>
    </plugin>
  </gazebo>

  <gazebo reference="lidar_link">
    <sensor type="ray" name="lidar">
      <visualize>true</visualize>
      <update_rate>10</update_rate>
      <ray>
        <scan><horizontal><samples>360</samples><resolution>1</resolution><min_angle>-3.14159</min_angle><max_angle>3.14159</max_angle></horizontal></scan>
        <range><min>0.3</min><max>30.0</max><resolution>0.01</resolution></range>
      </ray>
      <plugin name="lidar_plugin" filename="libgazebo_ros_ray_sensor.so">
        <ros><remapping>~/out:=scan</remapping></ros>
        <output_type>sensor_msgs/LaserScan</output_type>
        <frame_name>lidar_link</frame_name>
      </plugin>
    </sensor>
  </gazebo>

  <gazebo reference="camera_link">
    <sensor type="camera" name="camera">
      <update_rate>30.0</update_rate>
      <camera name="head">
        <horizontal_fov>1.3962634</horizontal_fov>
        <image>
          <width>640</width>
          <height>480</height>
          <format>R8G8B8</format>
        </image>
        <clip><near>0.02</near><far>300</far></clip>
      </camera>
      <plugin name="camera_controller" filename="libgazebo_ros_camera.so">
        <alwaysOn>true</alwaysOn>
        <updateRate>0.0</updateRate>
        <cameraName>ika/camera</cameraName>
        <imageTopicName>image_raw</imageTopicName>
        <cameraInfoTopicName>camera_info</cameraInfoTopicName>
        <frameName>camera_link</frameName>
      </plugin>
    </sensor>
  </gazebo>

  <gazebo>
    <plugin name="imu_plugin" filename="libgazebo_ros_imu_sensor.so">
      <ros><remapping>~/out:=imu/data</remapping></ros>
      <body_name>base_link</body_name>
      <update_rate_hz>30.0</update_rate_hz>
      <gaussian_noise>0.0</gaussian_noise>
    </plugin>
  </gazebo>

</robot>
