<?xml version="1.0" ?>
<robot name="ika">

  <!-- Materials -->
  <material name="blue"><color rgba="0 0 0.8 1"/></material>
  <material name="black"><color rgba="0 0 0 1"/></material>
  <material name="grey"><color rgba="0.5 0.5 0.5 1"/></material>

  <link name="base_footprint"/>
  <joint name="base_joint" type="fixed">
    <parent link="base_footprint"/><child link="base_link"/>
    <origin xyz="0 0 0.36" rpy="0 0 0"/>
  </joint>

  <link name="base_link">
    <visual><geometry><box size="1.3 1.15 0.72"/></geometry><material name="blue"/></visual>
    <collision><geometry><box size="1.3 1.15 0.72"/></geometry></collision>
    <inertial><mass value="50.0"/><inertia ixx="10.0" ixy="0" ixz="0" iyy="10.0" iyz="0" izz="15.0"/></inertial>
  </link>

  <!-- Wheels -->
  <link name="rl_wheel">
    <visual><origin rpy="1.5707 0 0"/><geometry><cylinder radius="0.2" length="0.08"/></geometry><material name="black"/></visual>
    <collision><origin rpy="1.5707 0 0"/><geometry><cylinder radius="0.2" length="0.08"/></geometry></collision>
    <inertial><mass value="2.5"/><inertia ixx="0.03" ixy="0" ixz="0" iyy="0.03" iyz="0" izz="0.05"/></inertial>
  </link>
  <joint name="rl_wheel_joint" type="continuous">
    <parent link="base_link"/><child link="rl_wheel"/><origin xyz="-0.4 0.575 -0.16"/><axis xyz="0 1 0"/>
  </joint>

  <link name="rr_wheel">
    <visual><origin rpy="1.5707 0 0"/><geometry><cylinder radius="0.2" length="0.08"/></geometry><material name="black"/></visual>
    <collision><origin rpy="1.5707 0 0"/><geometry><cylinder radius="0.2" length="0.08"/></geometry></collision>
    <inertial><mass value="2.5"/><inertia ixx="0.03" ixy="0" ixz="0" iyy="0.03" iyz="0" izz="0.05"/></inertial>
  </link>
  <joint name="rr_wheel_joint" type="continuous">
    <parent link="base_link"/><child link="rr_wheel"/><origin xyz="-0.4 -0.575 -0.16"/><axis xyz="0 1 0"/>
  </joint>

  <!-- LiDAR & Camera links remain same -->
  <link name="lidar_link">
    <visual><geometry><cylinder radius="0.05" length="0.05"/></geometry><material name="black"/></visual>
  </link>
  <joint name="lidar_joint" type="fixed">
    <parent link="base_link"/><child link="lidar_link"/><origin xyz="0.5 0 0.385"/>
  </joint>

  <link name="camera_link">
    <visual><geometry><box size="0.05 0.1 0.05"/></geometry><material name="grey"/></visual>
  </link>
  <joint name="camera_joint" type="fixed">
    <parent link="base_link"/><child link="camera_link"/><origin xyz="0.65 0 0.2"/>
  </joint>

  <!-- Gazebo Sim (Ignition) Plugins -->
  <gazebo>
    <!-- Diff Drive -->
    <plugin filename="gz-sim-diff-drive-system" name="gz::sim::systems::DiffDrive">
      <left_joint>rl_wheel_joint</left_joint>
      <right_joint>rr_wheel_joint</right_joint>
      <wheel_separation>1.15</wheel_separation>
      <wheel_radius>0.2</wheel_radius>
      <odom_publish_frequency>30</odom_publish_frequency>
      <topic>cmd_vel</topic>
      <odom_topic>odom</odom_topic>
      <tf_topic>tf</tf_topic>
      <frame_id>odom</frame_id>
      <child_frame_id>base_footprint</child_frame_id>
    </plugin>

    <!-- Joint State Publisher for Wheels -->
    <plugin filename="gz-sim-joint-state-publisher-system" name="gz::sim::systems::JointStatePublisher">
      <topic>joint_states</topic>
    </plugin>

    <!-- Sensors System -->
    <plugin filename="gz-sim-sensors-system" name="gz::sim::systems::Sensors">
      <render_engine>ogre2</render_engine>
    </plugin>

    <!-- IMU -->
    <plugin filename="gz-sim-imu-system" name="gz::sim::systems::Imu">
    </plugin>
  </gazebo>

  <!-- Sensor Definitions -->
  <gazebo reference="lidar_link">
    <sensor type="gpu_lidar" name="lidar">
      <pose>0 0 0 0 0 0</pose>
      <visualize>true</visualize>
      <update_rate>10</update_rate>
      <ray>
        <scan><horizontal><samples>360</samples><resolution>1</resolution><min_angle>-3.14159</min_angle><max_angle>3.14159</max_angle></horizontal></scan>
        <range><min>0.3</min><max>30.0</max></range>
      </ray>
      <topic>scan</topic>
      <gz_frame_id>lidar_link</gz_frame_id>
    </sensor>
  </gazebo>

  <gazebo reference="camera_link">
    <sensor type="camera" name="camera">
      <update_rate>30.0</update_rate>
      <topic>camera/image_raw</topic>
      <camera name="head">
        <horizontal_fov>1.396</horizontal_fov>
        <image><width>640</width><height>480</height><format>R8G8B8</format></image>
        <clip><near>0.02</near><far>300</far></clip>
      </camera>
    </sensor>
  </gazebo>

  <gazebo reference="base_link">
    <sensor name="imu_sensor" type="imu">
      <always_on>1</always_on>
      <update_rate>30</update_rate>
      <visualize>true</visualize>
      <topic>imu/data</topic>
    </sensor>
  </gazebo>

</robot>
